<?xml version="1.0"?>

<robot name="delta_robot">

  <!-- Define materials -->
  <material name="black">
    <color rgba="0 0 0 1"/>
  </material>

  <material name="white">
    <color rgba="1 1 1 1"/>
  </material>

  <!-- Define links -->
  <link name="base_link">
    <visual>
      <origin xyz="0 0 0" rpy="0 0 0"/>
      <geometry>
        <box size="0.02 0.02 0.2"/>
      </geometry>
      <material name="black"/>
    </visual>
    <inertial>
      <origin xyz="0 0 0" rpy="0 0 0"/>
      <mass value="2.0"/>
      <inertia ixx="0.0001" ixy="0" ixz="0" iyy="0.0001" iyz="0" izz="0.0001"/>
    </inertial>
  </link>

  <link name="platform">
    <visual>
      <origin xyz="0 0 0" rpy="0 0 0"/>
      <geometry>
        <box size="0.24 0.24 0.02"/>
      </geometry>
      <material name="black"/>
    </visual>
    <inertial>
      <origin xyz="0 0 -0.05" rpy="0 0 0"/>
      <mass value="2.0"/>
      <inertia ixx="0.0001" ixy="0" ixz="0" iyy="0.0001" iyz="0" izz="0.0001"/>
    </inertial>
  </link>

  <link name="driver_link">
    <visual>
      <origin xyz="0 0 0" rpy="0 0 0"/>
      <geometry>
        <box size="0.2 0.2 0.02"/>
      </geometry>
      <material name="white"/>
    </visual>
    <inertial>
      <origin xyz="0 0 -0.1" rpy="0 0 0"/>
      <mass value="1.5"/>
      <inertia ixx="0.0001" ixy="0" ixz="0" iyy="0.0001" iyz="0" izz="0.0001"/>
    </inertial>
  </link>

  <link name="driven_link">
    <visual>
      <origin xyz="0 0 0" rpy="0 0 0"/>
      <geometry>
        <box size="0.4 0.02 0.02"/>
      </geometry>
      <material name="white"/>
    </visual>
    <inertial>
      <origin xyz="0 0 -0.1" rpy="0 0 0"/>
      <mass value="0.133"/>
      <inertia ixx="0.0001" ixy="0" ixz="0" iyy="0.0001" iyz="0" izz="0.0001"/>
    </inertial>
  </link>

  <!-- Define joints -->
  <joint name="joint_base_platform" type="fixed">
    <parent link="base_link"/>
    <child link="platform"/>
    <origin xyz="0 0 0.1" rpy="0 0 0"/>
  </joint>

  <joint name="joint_driver_platform" type="fixed">
    <parent link="platform"/>
    <child link="driver_link"/>
    <origin xyz="0 0 0.01" rpy="0 0 0"/>
  </joint>

  <joint name="joint_driver_driven" type="prismatic">
    <parent link="driver_link"/>
    <child link="driven_link"/>
    <origin xyz="0 0 0.01" rpy="0 0 0"/>
    <axis xyz="1 0 0"/>
    <limit lower="-0.4" upper="0" effort="10" velocity="1"/>
  </joint>

  <!-- URDF transmission tags -->
  <transmission name="joint_driver_driven_trans">
    <type>transmission_interface/SimpleTransmission</type>
    <joint name="joint_driver_driven">
      <hardwareInterface>hardware_interface/PositionJointInterface</hardwareInterface>
    </joint>
    <actuator name="motor_driver_driven">
      <mechanicalReduction>1</mechanicalReduction>
    </actuator>
  </transmission>

</robot>

